{
  "timestamp": "2025-04-19T19:05:47.179887Z",
  "file": "<unknown>",
  "annotated_code": "import:py from jaclang.runtimelib.gins.smart_assert, smart_assert ;  # bb2 \u2192 bb3 [exec=0, time=0.0000s] | bb1 \u2192 bb3 [exec=0, time=0.0000s] | bb0 \u2192 bb2, bb1 [exec=0, time=0.0000s]\nimport:py from examples.gins_scripts.smart_assert.python_files.algorithms, factorial ;  # bb4 \u2192 bb6 [exec=0, time=0.0000s] | bb3 \u2192 bb5, bb4 [exec=0, time=0.0000s] | bb5 \u2192 bb6 [exec=0, time=0.0000s]\n\nwith entry {\n\n    testcases = [(0, 1), (1, 1), (3, 6), (5, 120), (6, 720)];      # bb6 \u2192 bb7 [exec=0, time=0.0000s]\n    for (idx, (inp, expected)) in enumerate(testcases, 1) {  # bb8 [exec=0, time=0.0000s] | bb7 \u2192 bb8, bb7 [exec=0, time=0.0000s] | bb6 \u2192 bb7 [exec=0, time=0.0000s]\n\n        got = factorial(inp);      # bb7 \u2192 bb8, bb7 [exec=0, time=0.0000s]\n        smart_assert(got == expected) ;  # bb7 \u2192 bb8, bb7 [exec=0, time=0.0000s]\n    }\n}\n",
  "llm_response": "The error message \"A smart assertion failed during program execution\" indicates that the `smart_assert` function within the loop encountered a case where `got` (the calculated factorial) was not equal to `expected` (the pre-defined value).  The provided execution information shows that the code hasn't actually run yet (all execution counts are 0).  This means the failure happened *during a subsequent execution* of the code, not in the initial profiling or compilation stage shown in the annotation.\n\n**Why the failure occurred:**\n\nThe failure is due to a discrepancy between the calculated factorial (`got`) and the expected factorial (`expected`) for at least one test case in the `testcases` list.  There are several possibilities:\n\n1. **Incorrect `factorial` function:** The `factorial` function in `examples.gins_scripts.smart_assert.python_files.algorithms` is buggy and doesn't correctly calculate the factorial for some inputs.  This is the most likely cause.  A common error is handling the base case (factorial of 0 or 1) incorrectly or having an off-by-one error in the loop.\n\n2. **Incorrect test cases:** One or more of the tuples in the `testcases` list contains an incorrect `expected` value.  Double-check the expected factorial values for each input.\n\n3. **Environment Issues:**  While less likely, there might be issues with the runtime environment (e.g., incompatible libraries, incorrect Python version) affecting the calculation.\n\n\n**How to prevent or fix the failure:**\n\n1. **Debug the `factorial` function:**  Print intermediate values within the `factorial` function to trace its execution for each input value in `testcases`. Use a debugger to step through the code line by line.\n\n2. **Verify `testcases`:** Manually calculate the factorial of each input in `testcases` and confirm that the `expected` values are correct.  A simple calculator or a separate factorial function (written for verification purposes) can help here.\n\n3. **Check for runtime errors:**  Examine the full error message (not just \"smart assertion failed\").  The complete message might indicate a specific error like a `ZeroDivisionError`, `RecursionError`, or `OverflowError` that reveals the problem in the `factorial` function.\n\n4. **Add more test cases:** Expand the `testcases` list to include more inputs, particularly edge cases like 0, 1, and larger numbers, to improve test coverage.\n\n5. **Use a different assertion method:** If you suspect environmental issues, try using Python's built-in `assert` statement instead of the custom `smart_assert`.  While it won't provide the same level of detail, it will confirm if the problem is specific to `smart_assert` or a more fundamental calculation error.\n\n\n**Example of Debugging:**\n\nLet's assume the `factorial` function is the problem.  You could modify it to include print statements:\n\n```python\ndef factorial(n):\n    print(f\"Calculating factorial for n = {n}\")\n    if n == 0:\n        print(f\"Base case: n=0, returning 1\")\n        return 1\n    else:\n        result = 1\n        for i in range(1, n + 1):\n            result *= i\n            print(f\"Iteration {i}: result = {result}\")\n        return result\n\n```\n\nBy running the code with these print statements, you'll see the intermediate calculations for each input, making it easier to pinpoint the source of the error. Remember to remove these debug prints once the problem is resolved.\n"
}