{
  "timestamp": "2025-04-19T22:41:46.331625Z",
  "file": "test_factorial.jac",
  "llm_responses": {
    "source_only": "The assertion `smart_assert(1 == 2)` is the cause of the failure.  This assertion explicitly checks if 1 is equal to 2, which is false.  The `smart_assert` function, presumably designed for testing, will raise an error because the condition is not met.\n\nThe error message \"smart assertion failed (view: source_only)\" indicates that the failure originated from within the `smart_assert` function itself, and the \"source_only\" part suggests that the detailed error information is only available by looking at the `smart_assert` function's source code (which we don't have access to here).\n\nTo fix this, you have a few options:\n\n1. **Correct the assertion:**  If the intention was to test the `factorial` function, the `smart_assert` call should be within the loop, comparing the `got` value (the result of `factorial`) with the `expected` value:\n\n```jac\nimport:py from jaclang.runtimelib.gins.smart_assert, smart_assert ;\nimport:py from examples.gins_scripts.smart_assert.python_files.algorithms, factorial ;\n\nwith entry {\n\n    testcases = [ (1, 1), (3, 6), (5, 120), (6, 720), (0, 1)];    \n    for (idx, (inp, expected)) in enumerate(testcases, 1) {\n\n        got = factorial(inp);    \n        smart_assert(got == expected, f\"Test case {idx} failed: factorial({inp}) expected {expected}, got {got}\"); // Improved error message\n        print(f\"Test case {idx} passed\"); // Indicate success\n    }\n    // Remove the incorrect assertion: smart_assert(1 == 2) ;\n}\n```\n\nThis version correctly tests each test case.  The added `f-string` in the `smart_assert` provides a much more informative error message if a test fails.  It also includes a message indicating success for each test case.\n\n2. **Remove the incorrect assertion:** If the `smart_assert(1 == 2)` was a leftover debugging statement, simply remove it.\n\n3. **Investigate the `smart_assert` function:** If you suspect a problem with the `smart_assert` function itself (e.g., it's not handling exceptions correctly), you'll need to examine its source code to debug it.\n\n\nIn summary, the problem is a flawed assertion. The solution is to either correct the assertion to properly test the `factorial` function or to remove the faulty assertion if it was unintended.  The improved code above provides a much more robust and informative testing mechanism.",
    "with_bb": "The assertion `smart_assert(1 == 2)` is failing because `1 == 2` is false.  The `smart_assert` function, presumably designed for testing, is designed to halt execution and signal an error if the condition passed to it is false.\n\nThe problem isn't in the `factorial` function or the test cases (those seem unrelated to the failure), but in the final assertion line.  This line is deliberately failing the test to demonstrate the assertion's behavior.\n\n**To fix the failure (if you intend for the assertion to pass):**\n\nChange `smart_assert(1 == 2)` to a true statement, such as:\n\n`smart_assert(1 == 1)`\n\nor\n\n`smart_assert(True)`\n\n\n**To understand the failure better:**\n\nThe annotated code shows that the `smart_assert` call executes, and since `1 == 2` evaluates to `False`, the assertion triggers. The \"smart\" aspect likely involves more detailed error reporting or handling than a standard `assert` statement in Python, perhaps including additional debugging information or logging.  The error message \"smart assertion failed (view: with_bb)\" suggests the failure is associated with a specific code block (identified as \"with_bb\").\n\nThe `factorial` function and test cases are present, but the assertion failure is entirely independent of their correctness.  The testcases loop completes successfully, but the final explicit `smart_assert` call causes the error.",
    "with_instr": "The assertion failure is caused by the line `smart_assert(1 == 2)`.  This assertion explicitly checks if 1 is equal to 2, which is false.  The `smart_assert` function, presumably designed to halt execution if a condition is not met, is doing exactly that.  The error message \"smart assertion failed\" confirms this.\n\nThe problem isn't in the logic of the `factorial` function itself (although you should test that separately to ensure its correctness), but in the final assertion added outside the loop. This assertion is always going to fail.\n\n**How to fix it:**\n\n1. **Remove the failing assertion:** If the `smart_assert(1 == 2)` line is intended as a test to see if the `smart_assert` function works, remove it after testing. It's not a meaningful part of verifying the `factorial` function.\n\n2. **Correctly use `smart_assert` within the loop:**  The current loop structure doesn't actually use `smart_assert` to check the results of the `factorial` function.  It should compare the `got` value (the result of `factorial`) with the `expected` value. The `print(\"test\")` statement is also irrelevant to verifying correctness.\n\nHere's the corrected code:\n\n```jac\nimport:py from jaclang.runtimelib.gins.smart_assert, smart_assert ;\nimport:py from examples.gins_scripts.smart_assert.python_files.algorithms, factorial ;\n\nwith entry {\n\n    testcases = [ (1, 1), (3, 6), (5, 120), (6, 720), (0, 1)];    \n    for (idx, (inp, expected)) in enumerate(testcases, 1) {\n        got = factorial(inp);    \n        smart_assert(got == expected) ; # Correct assertion here\n    }\n    // smart_assert(1 == 2) ;  // Removed - this was causing the failure\n}\n```\n\nThis revised code uses `smart_assert` to compare the calculated factorial (`got`) with the expected value from the `testcases` list for each input.  This correctly verifies the function's output.  Remember to test your `factorial` function independently to ensure it's producing the correct results before relying on these assertions.  If the `factorial` function is incorrect, the assertions will fail even after this fix.",
    "with_vars": "The smart assertion failure is occurring because the line `smart_assert(1 == 2)` is explicitly asserting that 1 is equal to 2, which is false.  This is not a problem with the factorial function or the loop; it's a deliberate (and incorrect) assertion.\n\nThe error message \"smart assertion failed (view: with_vars)\" indicates that the assertion failed and the `with_vars` context (likely part of the Jac language's debugging mechanism) is showing you the variables at the point of failure.\n\n**How to fix it:**\n\nThe problem isn't in the logic of calculating factorials; the problem is the intentionally incorrect assertion.  You need to change the assertion to something that reflects the actual test results of your `factorial` function.  To correctly use `smart_assert`, you should check the results of each factorial calculation within the loop.\n\nHere's the corrected code:\n\n```jac\nimport:py from jaclang.runtimelib.gins.smart_assert, smart_assert ;\nimport:py from examples.gins_scripts.smart_assert.python_files.algorithms, factorial ;\n\nwith entry {\n\n    testcases = [ (1, 1), (3, 6), (5, 120), (6, 720), (0, 1)];    \n    for (idx, (inp, expected)) in enumerate(testcases, 1) {\n\n        got = factorial(inp);    \n        smart_assert(got == expected, f\"Test case {idx} failed: factorial({inp}) expected {expected}, got {got}\");\n        print(f\"Test case {idx} passed\") ; #Optional: Print success message\n    }\n    // Remove this incorrect assertion:\n    // smart_assert(1 == 2) ;\n\n}\n```\n\nThis revised code incorporates the following changes:\n\n* **Assertion within the loop:** The `smart_assert` is now inside the loop, checking `got == expected` for each test case.\n* **Informative error message:**  An f-string provides a clear error message if a test fails, including the test case number, input, expected output, and actual output. This greatly improves debugging.\n* **Removal of the incorrect assertion:** The `smart_assert(1 == 2)` line is removed, as it's the source of the error.\n\n\nThis corrected code will now accurately test the `factorial` function and report failures appropriately.  If the `factorial` function is correctly implemented, all test cases should pass.  If a test fails, the error message will pinpoint the specific failing test case.",
    "complete": "The assertion `smart_assert(1 == 2)` on line 8 is failing because `1 == 2` evaluates to `False`.  The `smart_assert` function (presumably a custom assertion function) is designed to raise an error if the condition provided to it is false.  This is intentional behavior, designed to signal a test failure.\n\nThe error isn't in the code *itself*, but in the *logic* of the test case.  The test is asserting that 1 is equal to 2, which is incorrect.  This is a failing test case, not a bug in the code's execution or the `smart_assert` function.\n\n\n**How to fix it:**\n\nThe solution depends on what you're trying to achieve.  There are a few possibilities:\n\n1. **Correct the assertion:** If the intention was to test the `factorial` function, the `smart_assert` call should reflect the expected results of the factorial function.  This line is completely separate from the loop testing the factorial function and is therefore a standalone, failing assertion.\n\n2. **Remove the failing assertion:**  If the `smart_assert(1 == 2)` statement was added for testing purposes and is no longer needed, simply remove the line.\n\n3. **Add more comprehensive assertions within the loop:** The loop already iterates through test cases.  Instead of a separate assertion, you could incorporate assertions *inside* the loop to check if `got` equals `expected` for each test case.  This would provide more informative feedback on which specific input caused the failure.  Example:\n\n\n```python\nimport:py from jaclang.runtimelib.gins.smart_assert, smart_assert\nimport:py from examples.gins_scripts.smart_assert.python_files.algorithms, factorial\n\nwith entry {\n\n    testcases = [ (1, 1), (3, 6), (5, 120), (6, 720), (0, 1)];\n    for (idx, (inp, expected)) in enumerate(testcases, 1) {\n        got = factorial(inp);\n        smart_assert(got == expected, f\"Factorial of {inp} should be {expected}, but got {got}\") #Improved assertion\n        #print(\"test\");  //Remove or comment out the unnecessary print statement.\n    }\n    # smart_assert(1 == 2) ; //Remove this line - it is always going to fail.\n}\n```\n\nThis revised code uses a more informative error message within the `smart_assert` call.  If a test case fails, the message will indicate which input value caused the failure.  This makes debugging much easier.  The standalone failing assertion has been removed.  The `print(\"test\")` statement is also unnecessary and could be removed for cleaner code.\n\n\nRemember to choose the solution that best reflects the desired behavior of your test suite. The original error message simply indicates a deliberate and expected failure of a test assertion.  The key is to make the assertions reflect the actual tests you intend to perform."
  }
}